Workbook

Sheet SUMUP 
C4: Business Unit (BU) | H4: Lines of Business (LOB) | L4: Connectable products | O4: Supects products | R4: TOTAL | T4: These amounts of product in each lob are not completely exhaustive same as the protocols listed within the list
C7: Industrial Automation | H7: Process Automation | L7: 78 | O7: 14 | R7: =SUM(L7:Q7) -> 92
H8: Digital Factory | L8: 28 | O8: 5 | R8: =SUM(L8:Q8) -> 33
H9: Industrial Control & Drives | L9: 26 | O9: 0 | R9: =SUM(L9:Q9) -> 26
C11: AVEVA | H11: AVEVA | L11: 86 | O11: 0 | R11: =SUM(L11:Q11) -> 86
C13: Energy Management | H13: Digital Power | L13: 111 | O13: 0 | R13: =SUM(L13:Q13) -> 111
H14: Digital Building | L14: 37 | O14: 5 | R14: =SUM(L14:Q14) -> 42
H15: Secure Power | L15: 71 | O15: 18 | R15: =SUM(L15:Q15) -> 89
H16: Power Products | L16: 19 | O16: 7 | R16: =SUM(L16:Q16) -> 26
H17: Power Systems | L17: 0 | O17: 22 | R17: =SUM(L17:Q17) -> 22
H18: Home & Distribution | L18: 8 | O18: 0 | R18: =SUM(L18:Q18) -> 8
C20: Innovation at the Edge | H20: Digital Grid | L20: 7 | O20: 0 | R20: =SUM(L20:Q20) -> 7
H21: eMobility | L21: 1 | O21: 0 | R21: =SUM(L21:Q21) -> 1
H22: Energy storage & Solar | L22: 0 | O22: 1 | R22: =SUM(L22:Q22) -> 1
H23: Company portfolio | L23: 0 | O23: 9 | R23: =SUM(L23:Q23) -> 9
H24: TOTAL | L24: =SUM(L7:N9,L11,L13:N18,L20:N23) -> 472 | O24: =SUM(O7:Q9,O11,O13:Q18,O20:Q23) -> 81 | R24: =SUM(R7:R9,R11,R13:R18,R20:R23) -> 553
D28: Business Unit (BU) | I28: Lines of Business (LOB) | M28: Product Ranges | P28: Product Ranges w/ Fingerprints | S28: Percentages of Ranges visible on the public internet
D31: Industrial Automation | I31: Process Automation | M31: 83 | P31: 17 | S31: =(P31/M31) -> 0.20481928
I32: Digital Factory | M32: 35 | P32: 8 | S32: =(P32/M32) -> 0.22857143
I33: Industrial Control & Drives | M33: 26 | P33: 4 | S33: =(P33/M33) -> 0.15384615
D34: Energy Management | I34: Digital Power | M34: 111 | P34: 22 | S34: =(P34/M34) -> 0.1981982
I35: Digital Building | M35: 42 | P35: 15 | S35: =(P35/M35) -> 0.35714286
I36: Secure Power | M36: 89 | P36: 14 | S36: =(P36/M36) -> 0.15730337
I37: Power Products | M37: 26 | P37: 2 | S37: =(P37/M37) -> 0.076923077
I38: Power Systems | M38: 22 | P38: 1 | S38: =(P38/M38) -> 0.045454545
I39: Home & Distribution | M39: 8 | P39: 3 | S39: =(P39/M39) -> 0.375
I40: TOTAL | M40: =SUM(M31:O39) -> 442 | P40: =SUM(P31:R39) -> 86 | S40: =(P40/M40) -> 0.19457014
D45: Business Unit (BU) | I45: Product Ranges | L45: Product Ranges with Fingerprints | O45: % | T45: Business Unit (BU) | Y45: Product Ranges | AB45: Product Ranges with Fingerprints | AE45: %
D47: Industrial Automation | I47: =COUNTA('Industrial Automation'!D3:D153) -> 151 | L47: =COUNTIF('Industrial Automation'!C3:C153,"Yes") -> 30 | O47: =L47/I47 -> 0.1986755 | T47: Industrial Automation | Y47: 146 | AB47: 30 | AE47: 0.20547945
D48: Energy Management | I48: =COUNTA('Digital Power'!D3:D172)+COUNTA('Digital Building'!A3:A50)+COUNTA('Secure Power (OLD)'!E3:E95)+COUNTA('Power Products'!E3:E24)+COUNTA('Power System'!D3:D24)+COUNTA('Home & Distribution'!C3:C7) -> 354 | L48: =COUNTIF('Digital Power'!#REF!, "Yes")+COUNTIF('Digital Building'!#REF!, "Yes")+COUNTIF('Secure Power (OLD)'!A3:A95, "Yes")+COUNTIF('Power Products'!#REF!, "Yes")+COUNTIF('Power System'!#REF!, "Yes")+COUNTIF('Home & Distribution'!#REF!, "Yes") -> #REF! | O48: =L48/I48 -> #REF! | T48: Energy Management | Y48: 298 | AB48: 57 | AE48: 0.19127517
I49: =I47+I48 -> 505 | L49: =L47+L48 -> #REF! | O49: =L49/I49 -> #REF! | Y49: 444 | AB49: 87 | AE49: 0.19594595
E51: Digital Power | I51: =COUNTA('Digital Power'!D3:D172) -> 170 | L51: =COUNTIF('Digital Power'!#REF!, "Yes") -> #REF! | O51: =L51/I51 -> #REF! | U51: Digital Power | Y51: 111 | AB51: 22 | AE51: 0.1981982
E52: Digital Building | I52: =COUNTA('Digital Building'!A3:A50) -> 44 | L52: =COUNTIF('Digital Building'!#REF!, "Yes") -> #REF! | O52: =L52/I52 -> #REF! | U52: Digital Building | Y52: 42 | AB52: 15 | AE52: 0.35714286
E53: Secure Power | I53: =COUNTA('Secure Power (OLD)'!E3:E95) -> 93 | L53: =COUNTIF('Secure Power (OLD)'!A3:A95, "Yes") -> 4 | O53: =L53/I53 -> 0.043010753 | U53: Secure Power | Y53: 89 | AB53: 14 | AE53: 0.15730337
E54: Power Products | I54: =COUNTA('Power Products'!E3:E24) -> 22 | L54: =COUNTIF('Power Products'!#REF!, "Yes") -> #REF! | O54: =L54/I54 -> #REF! | U54: Power Products | Y54: 26 | AB54: 2 | AE54: 0.076923077
E55: Power Systems | I55: =COUNTA('Power System'!D3:D24) -> 22 | L55: =COUNTIF('Power System'!#REF!, "Yes") -> #REF! | O55: =L55/I55 -> #REF! | U55: Power Systems | Y55: 22 | AB55: 1 | AE55: 0.045454545
E56: Home & Distribution | I56: =COUNTA('Home & Distribution'!C3:C7) -> 3 | L56: =+COUNTIF('Home & Distribution'!#REF!, "Yes") -> #REF! | O56: =L56/I56 -> #REF! | U56: Home & Distribution | Y56: 8 | AB56: 3 | AE56: 0.375
I57: =SUM(I51:K56) -> 354 | L57: =SUM(L51:N56) -> #REF! | O57: =L57/I57 -> #REF! | Y57: 298 | AB57: 57 | AE57: 0.19127517

Sheet Summary Sheet
B3: BU | C3: LOB | D3: No. of Connected Product Ranges | E3: Detection Status - SE Product Ranges | I3: Total Detection Capability (No, %) | L3: Review Status
E4: Seen on BS | F4: Seen on Shodan & Censys | G4: Seen across all 3 platforms | H4: Additional Capability Internal (Y) + BS (N)
B5: Industrial Automation | C5: Digital Factory | D5: ='Industrial Automation'!D1 -> 151 | E5: ='Industrial Automation'!B1 -> 43 | F5: ='Industrial Automation'!C1 -> 30 | G5: 11 | H5: 19 | I5: =E5+H5 -> 62 | J5: =(E5+H5)/D5 -> 0.41059603 | L5: Done
C6: Industrial Controls & Drives
C7: Process Automation
B8: Energy Management | C8: Digital Buildings (D. Energy) | D8: ='Digital Building'!C1 -> 48 | E8: ='Digital Building'!A1 -> 11 | F8: ='Digital Building'!B1 -> 15 | G8: =COUNTIFS('Digital Building'!A:A,"Yes",'Digital Building'!B:B,"Yes") -> 5 | H8: =COUNTIFS('Digital Building'!A:A,"No",'Digital Building'!B:B,"Yes") -> 10 | I8: =E8+H8 -> 21 | J8: =(H8+E8)/D8 -> 0.4375
C9: Digital Power (D. Energy) | D9: ='Digital Power'!D1 -> 170 | E9: ='Digital Power'!B1 -> 27 | F9: ='Digital Power'!C1 -> 21 | G9: =COUNTIFS('Digital Power'!B:B,"Yes",'Digital Power'!C:C,"Yes") -> 8 | H9: =COUNTIFS('Digital Power'!B:B,"No",'Digital Power'!C:C,"Yes") -> 13 | I9: =E9+H9 -> 40 | J9: =(H9+E9)/D9 -> 0.23529412 | L9: Review pending
C10: MicroGrid (D. Energy) | D10: =MicroGrid!D1 -> 15 | E10: =MicroGrid!B1 -> 0 | F10: =MicroGrid!C1 -> 0 | G10: =COUNTIFS(MicroGrid!B:B,"Yes",MicroGrid!C:C,"Yes") -> 0 | H10: =COUNTIFS(MicroGrid!B:B,"No",MicroGrid!C:C,"Yes") -> 0 | I10: =E10+H10 -> 0 | J10: =(H10+E10)/D10 -> 0 | L10: Review pending
C11: EcoStruxure Power (D. Energy) | D11: ='EcoStruxure Power'!D1 -> 32 | E11: ='EcoStruxure Power'!B1 -> 1 | F11: ='EcoStruxure Power'!C1 -> 1 | G11: =COUNTIFS('EcoStruxure Power'!B:B,"Yes",'EcoStruxure Power'!C:C,"Yes") -> 0 | H11: =COUNTIFS('EcoStruxure Power'!B:B,"No",'EcoStruxure Power'!C:C,"Yes") -> 1 | I11: =E11+H11 -> 2 | J11: =(H11+E11)/D11 -> 0.0625 | L11: Review pending
C12: Secure Power | D12: ='Secure Power'!E1 -> 24 | E12: ='Secure Power'!A1 -> 3 | F12: ='Secure Power'!B1 -> 7 | G12: =COUNTIFS('Secure Power'!A:A,"Yes",'Secure Power'!B:B,"Yes") -> 0 | H12: =COUNTIFS('Secure Power'!A:A,"No",'Secure Power'!B:B,"Yes") -> 7 | I12: =E12+H12 -> 10 | J12: =(H12+E12)/D12 -> 0.41666667 | L12: Done
C13: Power Products | D13: ='Power Products'!E1 -> 22 | E13: ='Power Products'!C1 -> 5 | F13: ='Power Products'!D1 -> 2 | G13: =COUNTIFS('Power Products'!C:C,"Yes",'Power Products'!D:D,"Yes") -> 0 | H13: =COUNTIFS('Power Products'!C:C,"No",'Power Products'!D:D,"Yes") -> 2 | I13: =E13+H13 -> 7 | J13: =(H13+E13)/D13 -> 0.31818182 | L13: Done
C14: Home Solutions | D14: ='Home & Distribution'!C1 -> 3 | E14: ='Home & Distribution'!A1 -> 3 | F14: ='Home & Distribution'!B1 -> 1 | G14: =COUNTIFS('Home & Distribution'!A:A,"Yes",'Home & Distribution'!B:B,"Yes") -> 1 | H14: =COUNTIFS('Home & Distribution'!A:A,"No",'Home & Distribution'!B:B,"Yes") -> 0 | I14: =E14+H14 -> 3 | J14: =(H14+E14)/D14 -> 1 | L14: Done
C15: Power Systems | D15: ='Power System'!C1 -> 22 | E15: ='Power System'!A1 -> 0 | F15: ='Power System'!B1 -> 1 | G15: =COUNTIFS('Power System'!A:A,"Yes",'Power System'!B:B,"Yes") -> 0 | H15: =COUNTIFS('Power System'!A:A,"No",'Power System'!B:B,"Yes") -> 1 | I15: =E15+H15 -> 1 | J15: =(H15+E15)/D15 -> 0.045454545
B16: Innovation @ Edge | C16: Digital Grid | L16: Not Started
C17: eMobility | L17: Not Started
C19: Total | D19: =SUM(D5:D15) -> 487 | E19: =SUM(E5:E15) -> 93 | F19: =SUM(F5:F15) -> 78 | G19: =SUM(G5:G15) -> 25 | H19: =SUM(H5:H15) -> 53 | I19: =SUM(I5:I15) -> 146 | J19: Global Detection Status
D20: 1 | E20: =E19/D19 -> 0.19096509 | F20: =F19/D19 -> 0.16016427 | G20: =G19/D19 -> 0.051334702 | H20: =H19/D19 -> 0.10882957 | I20: =I19/D19 -> 0.29979466
B24: Assumptions / Activities done | E24: Action Needed
B25: All offers ranges have been manually identified. | E25: BU/LOB to confirm the list of offer ranges. Add/subtract based on latest updates available within the BU/LOB.
B26: Some offer ranges don't have connectable products | E26: Confirmation needed by the LOB. Those ranges to be removed from global list of connectable offers.
B29: Target state to achieve
B30: Final SE offers list with connectable products only as the baseline including legacy products (max 10 years).
B31: Fingerprints per product or product range to be

Sheet M-o-M
B2: 45689
B19: 45809
B41: 45870
B62: 45919

Sheet Capability Table
M2: 45689
B3: BU | C3: LOB | D3: No. of Connected Product Ranges | E3: Total Detection Capability (No, %)
B5: Industrial Automation | C5: Digital Factory | D5: ='Summary Sheet'!D5 -> 151 | E5: ='Summary Sheet'!I5 -> 62 | F5: =E5/D5 -> 0.41059603
C6: Industrial Controls & Drives
C7: Process Automation
B8: Energy Management | C8: Digital Power (D. Energy) | D8: ='Summary Sheet'!D9 -> 170 | E8: ='Summary Sheet'!I9 -> 40 | F8: =E8/D8 -> 0.23529412
C9: Digital Buildings (D. Energy) | D9: ='Summary Sheet'!D8 -> 48 | E9: ='Summary Sheet'!I8 -> 21 | F9: =E9/D9 -> 0.4375
C10: Secure Power | D10: ='Summary Sheet'!D12 -> 24 | E10: ='Summary Sheet'!I12 -> 10 | F10: =E10/D10 -> 0.41666667
C11: Power Products | D11: ='Summary Sheet'!D13 -> 22 | E11: ='Summary Sheet'!I13 -> 7 | F11: =E11/D11 -> 0.31818182
C12: Home & Distribution | D12: ='Summary Sheet'!D14 -> 3 | E12: ='Summary Sheet'!I14 -> 3 | F12: =E12/D12 -> 1
C13: Power Systems | D13: ='Summary Sheet'!D15 -> 22 | E13: ='Summary Sheet'!I15 -> 1 | F13: =E13/D13 -> 0.045454545
C14: Total | D14: =SUM(D5:D13) -> 440 | E14: =SUM(E5:E13) -> 144 | F14: Global Detection Status
D15: 1 | E15: =E14/D14 -> 0.32727273
R16: =153+119+44+93+28+14+22 -> 473
B19: Assumptions / Activities done
B20: All offers ranges have been manually identified.
B21: Some offer ranges don't have connectable products
N23: OT Protocols Detection
B24: Target state to achieve | N24: 2024 Ambition | O24: 10
B25: Final SE offers list with connectable products only as the baseline including legacy products (max 10 years). | N25: Actual | O25: 8
B26: Fingerprints per product or product range to be | N26: % | O26: =O25/O24 -> 0.8
C31: IA | D31: 155 | E31: 64
C32: DP | D32: 120 | E32: 45
C33: DB | D33: 44 | E33: 21
C34: SP | D34: 93 | E34: 18
C35: PP | D35: 21 | E35: 7
C36: H&D | D36: 9 | E36: 7
C37: Total | D37: =SUM(D31:D36) -> 442 | E37: =SUM(E31:E36) -> 162
E38: =E37/D37 -> 0.36651584

Sheet Industrial Automation
B1: =COUNTIF(Table54[Seen on BS],"Yes") -> 43 | C1: =COUNTIF(Table54[Fingerprints available], "Yes") -> 30 | D1: =COUNTA(Table54[[Product range ]]) -> 151 | E1: =SUBTOTAL(3,Table54[[Product range ]]) -> 151
A2: Priority | B2: Seen on BS | C2: Fingerprints available | D2: Product range | E2: Family | F2: LOB | G2: BU | H2: Type | I2: EcoStruxure Level | J2: State | K2: Notes | L2: Protocols | M2: BacNet | N2: EIP | O2: FTP | P2: HTTP/HTTPS | Q2: KNX | R2: mDNS | S2: Modbus Series | T2: ModbusTCP | U2: SNTP | V2: SNMP | W2: SQL Server | X2: Telnet | Y2: DNP3 | Z2: Web | AA2: SMTP | AB2: SFTP | AC2: 3,4G | AD2: Wifi , IPV4,6 | AE2: IEC 60870-5-103/104/101 | AF2: IEC 61850 | AG2: Zigbee | AH2: Other | AI2: Available at GSL B'lore
A3: High | B3: Yes | C3: No | D3: Advantys OTB | E3: PLC, PAC and dedicated controllers | F3: Process automation | G3: Industrial Automation | H3: HW | I3: Edge Control | J3: No information | L3: Modbus Serie, Modbus TCP | S3: Y | T3: Y
A4: High | B4: No | C4: No | D4: Advantys STB | E4: PLC, PAC and dedicated controllers | F4: Process automation | G4: Industrial Automation | H4: HW | I4: Edge Control | J4: Commercialized | L4: Modbus Serie, Modbus TCP | S4: Y | T4: Y
A5: Low | B5: No | C5: No | D5: ATS22 | E5: Variable speed drives | F5: Industrial control and drives | G5: Industrial Automation | H5: HW | I5: Connected product | J5: No information | L5: Modbus Serie, Modbus TCP | S5: Y
A6: Low | B6: No | C6: No | D6: ATS48 | E6: Variable speed drives | F6: Industrial control and drives | G6: Industrial Automation | H6: HW | I6: Connected product | J6: End of commercialisation | L6: Modbus Serie, Modbus TCP | S6: Y | T6: Y
A7: Low | B7: Yes | C7: No | D7: ATS480 | E7: Variable speed drives | F7: Industrial control and drives | G7: Industrial Automation | H7: HW | I7: Connected product | J7: Commercialized | L7: Modbus Serie, Modbus TCP | S7: Y | T7: Y
A8: Low | B8: No | C8: No | D8: ATV 212 | E8: Variable speed drives | F8: Industrial control and drives | G8: Industrial Automation | H8: HW | I8: Connected product | J8: Commercialized | L8: Bacnet, Modbus TCP | M8: Y | S8: Y
A9: Low | B9: No | C9: No | D9: ATV 212 (HVAC) | E9: Variable speed drives | F9: Process automation | G9: Industrial Automation | H9: HW | I9: Edge control | J9: Commercialized
A10: Low | B10: No | C10: No | D10: ATV 680 AFE | E10: Variable speed drives | F10: Industrial control and drives | G10: Industrial Automation | H10: HW | I10: Connected product | J10: Commercialized | L10: Modbus TCP | T10: Y | Z10: Y?
A11: Low | B11: No | C11: No | D11: ATV AFE | E11: Variable speed drives | F11: Industrial control and drives | G11: Industrial Automation | H11: HW | I11: Connected product | J11: No information | L11: Modbus TCP | T11: Y
A12: Low | B12: No | C12: No | D12: ATV12 | E12: Variable speed drives | F12: Industrial control and drives | G12: Industrial Automation | H12: HW | I12: Connected product | J12: Commercialized | L12: Modbus Serie, Modbus TCP | S12: Y
A13: Low | B13: No | C13: No | D13: ATV21 | E13: Variable speed drives | F13: Industrial control and drives | G13: Industrial Automation | H13: HW | I13: Connected product | J13: No information | L13: Bacnet, Modbus Serie? | M13: Y | S13: Y?
A14: Low | B14: Yes | C14: No | D14: ATV31 | E14: Variable speed drives | F14: Industrial control and drives | G14: Industrial Automation | H14: HW | I14: Connected product | J14: No information | L14: Modbus TCP | T14: Y
A15: Low | B15: No | C15: No | D15: ATV312 | E15: Variable speed drives | F15: Industrial control and drives | G15: Industrial Automation | H15: HW | I15: Connected product | J15: Commercialized | L15: Modbus Serie, Modbus TCP | S15: Y | T15: Y
A16: Low | B16: No | C16: No | D16: ATV32 | E16: Variable speed drives | F16: Industrial control and drives | G16: Industrial Automation | H16: HW | I16: Connected product | J16: End of commercialisation | L16: Modbus Serie, Modbus TCP | S16: Y | T16: Y
A17: Low | B17: Yes | C17: Yes | D17: ATV320 | E17: Variable speed drives | F17: Industrial control and drives | G17: Industrial Automation | H17: HW | I17: Connected product | J17: Commercialized | L17: Modbus Serie, Modbus TCP, FTP | N17: Y | S17: Y | T17: Y
A18: Low | B18: Yes | C18: No | D18: ATV340 | E18: Variable speed drives | F18: Industrial control and drives | G18: Industrial Automation | H18: HW | I18: Connected product | J18: Commercialized | N18: Y | T18: Y
A19: Low | B19: Yes | C19: Yes | D19: ATV600 | E19: Variable speed drives | F19: Industrial control and drives | G19: Industrial Automation | H19: HW | I19: Connected product | J19: Commercialized
A20: Low | B20: No | C20: No | D20: ATV6000 | E20: Variable speed drives | F20: Industrial control and drives | G20: Industrial Automation | H20: HW | I20: Connected product | J20: Commercialized | N20: Y | S20: Y | T20: Y
A21: Low | B21: Yes | C21: No | D21: ATV61 | E21: Variable speed drives | F21: Industrial control and drives | G21: Industrial Automation | H21: HW | I21: Connected product | J21: End of commercialisation | N21: Y | S21: Y | T21: Y
A22: Low | B22: No | C22: Yes | D22: ATV630 | E22: Variable speed drives | F22: Industrial control and drives | G22: Industrial Automation | H22: HW | I22: Connected product | J22: Commercialized | N22: Y | T22: Y
A23: Low | B23: No | C23: No | D23: ATV660 | E23: Variable speed drives | F23: Industrial control and drives | G23: Industrial Automation | H23: HW | I23: Connected product | J23: Commercialized | N23: Y
A24: Low | B24: No | C24: No | D24: ATV680 | E24: Variable speed drives | F24: Industrial control and drives | G24: Industrial Automation | H24: HW | I24: Connected product | J24: Commercialized | N24: Y | S24: Y | T24: Y
A25: Low | B25: No | C25: No | D25: ATV71 | E25: Variable speed drives | F25: Industrial control and drives | G25: Industrial Automation | H25: HW | I25: Connected product | J25: End of commercialisation | N25: Y | S25: Y | T25: Y
A26: Low | B26: Yes | C26: No | D26: ATV900 | E26: Variable speed drives | F26: Industrial control and drives | G26: Industrial Automation | H26: HW | I26: Connected product | J26: Commercialized
A27: Low | B27: No | C27: Yes | D27: ATV930 | E27: Variable speed drives | F27: Industrial control and drives | G27: Industrial Automation | H27: HW | I27: Connected product | J27: Commercialized | N27: Y | T27: Y
A28: Medium | B28: No | C28: No | D28: ClearSCADA , GeoSCADA | E28: Telemetry and remote SCADA | F28: Digital Factory | G28: Industrial Automation | H28: SW | I28: Edge control | J28: Commercialized | K28: Programming software | L28: Software
B29: No | C29: Yes | D29: EcoStruxure Architecture Builder | E29: Industrial Automation Software | F29: Process automation | G29: Industrial Automation | H29: SW | I29: Edge control | J29: Commercialized | K29: Programming software | L29: Software
B30: No | C30: Yes | D30: EcoStruxure Augmented Operator Advisor | F30: Digital Factory | G30: Industrial Automation | H30: SW | I30: Analytics | J30: Commercialized | L30: Software
A31: High | B31: No | C31: Yes | D31: EcoStruxure Automation Expert | E31: Industrial Automation Software | F31: Process automation | G31: Industrial Automation | H31: SW | I31: Edge control | J31: Commercialized | K31: Programming software | L31: Software
B32: No | C32: Yes | D32: EcoStruxure Autonomous Production Advisor | E32: Process control and safety | F32: Digital Factory | G32: Industrial Automation | H32: SW | I32: Analytics | J32: Commercialized | L32: Software
B33: No | C33: No | D33: EcoStruxure Clean-in-Place Advisor | E33: Digital Services | F33: Digital Factory | G33: Industrial Automation | H33: SW | I33: Analytics | J33: Commercialized | L33: Software
B34: No | C34: No | D34: EcoStruxure Compressor Performance Monitor | F34: Digital Factory | G34: Industrial Automation | H34: SW | I34: Edge control | J34: Commercialized | L34: Software
B35: No | C35: Yes | D35: EcoStruxure Control Advisor ,Demo | E35: Process control and safety | F35: Digital Factory | G35: Industrial Automation | H35: SW | I35: Analytics | J35: Commercialized | L35: Software
A36: High | B36: No | C36: Yes | D36: EcoStruxure Control Engineering | E36: PLC,PAC and Controllers | F36: Process automation | G36: Industrial Automation | H36: SW | I36: Edge control | J36: Commercialized | K36: Programming software | L36: Software
A37: High | B37: No | C37: No | D37: EcoStruxure Control Expert | E37: PLC,PAC and Controllers | F37: Process automation | G37: Industrial Automation | H37: SW | I37: Edge control | J37: Commercialized | K37: Programming software | L37: Software
B38: No | C38: No | D38: EcoStruxure Field Device Expert | F38: Digital Factory | G38: Industrial Automation | H38: SW | I38: Edge control | J38: Commercialized | K38: Programming software | L38: Software
A39: High | B39: No | C39: No | D39: EcoStruxure Foxboro DCS | E39: Process control and safety | F39: Digital Factory | G39: Industrial Automation | H39: SW | I39: Edge control | J39: Commercialized | L39: Software
B40: No | C40: Yes | D40: EcoStruxure Machine Advisor | E40: Industrial Automation Software | F40: Digital Factory | G40: Industrial Automation | H40: SW | I40: Analytics | J40: Commercialized | L40: Software
...

Sheet Digital Power
B1: =COUNTIF(Table32[Seen on BS],"Yes") -> 27 | C1: =COUNTIF(Table32[Fingerprints available],"Yes") -> 21 | D1: =COUNTA(Table32[Product range]) -> 170 | E1: =SUBTOTAL(3,D3:D172) -> 170
A2: Priority | B2: Seen on BS | C2: Fingerprints available | D2: Product range | E2: Family | F2: LOB | G2: BU | H2: Type | I2: EcoStruxure Level | J2: State | K2: Notes | L2: Protocols | M2: BacNet | N2: EIP | O2: FTP | P2: HTTP/HTTPS | Q2: KNX | R2: mDNS | S2: Modbus Series | T2: ModbusTCP | U2: SNTP | V2: SNMP | W2: SQL Server | X2: Telnet | Y2: DNP3 | Z2: Web | AA2: SMTP | AB2: SFTP | AC2: 3,4G | AD2: Wifi , IPV4,6 | AE2: IEC 60870-5-103/104/101 | AF2: IEC 61850 | AG2: Zigbee | AH2: Bluetooth | AI2: Available at GSL B'lore
B3: No | C3: No | D3: A9MEM2050, A9MEM2055, A9MEM2435, A9MEM2455 (Brand Label) | E3: Basic Metering | F3: Digital Power | G3: Energy Management | H3: HW | I3: Connected Product | J3: Commercialized | K3: Add from Product Portfolio RA
B4: No | C4: No | D4: Advanced Metering Platform | E4: Advanced Metering | F4: Digital Power | G4: Energy Management | H4: HW | I4: Connected Product | J4: Commercialized
B5: No | C5: No | D5: BCPME | E5: Advanced Metering | F5: Digital Power | G5: Energy Management | H5: HW | I5: Connected Product | J5: Commercialized
B6: No | C6: No | D6: C264 | E6: Power Management System | F6: Digital Power | G6: Energy Management | H6: HW | I6: Connected Product | J6: Commercialized | K6: Add from Product Portfolio FS
B7: No | C7: No | D7: C5 | E7: Power Management System | F7: Digital Power | G7: Energy Management | H7: HW | I7: Connected Product | J7: Commercialized | K7: Add from Product Portfolio FS
B8: No | C8: No | D8: CAE | E8: Power Management System | F8: Digital Power | G8: Energy Management | H8: SW | I8: Edge control | J8: Commercialized | K8: Add from Product Portfolio FS
B9: No | C9: No | D9: CAP | E9: Power Mgt Systems | F9: Digital Power | G9: Energy Management | H9: SW | I9: Edge control | J9: Commercialized | K9: Add from Product Portfolio DP LoB (Laura)
B10: No | C10: No | D10: Conductor MDM | E10: Medium Voltage Distribution and Grid Automation | H10: SW | I10: Edge control , Analytics | J10: Commercialized | L10: Software
B11: No | C11: No | D11: Curling Head Unit (system) | E11: Power Management System | F11: Digital Power | G11: Energy Management | H11: SW | I11: Edge control | K11: Add from Product Portfolio FS
B12: No | C12: No | D12: Curling Head Unit configurator | E12: Power Management System | F12: Digital Power | G12: Energy Management | H12: SW | I12: Edge control | K12: Add from Product Portfolio FS
B13: No | C13: No | D13: Curling Head Unit Hypervisor | E13: Power Management System | F13: Digital Power | G13: Energy Management | H13: SW | I13: Edge control | K13: Add from Product Portfolio FS
B14: No | C14: No | D14: Curling Head Unit Virtualized P7 | E14: Power Management System | F14: Digital Power | G14: Energy Management | H14: SW | I14: Edge control | K14: Add from Product Portfolio FS
B15: No | C15: No | D15: DIN RS485 600V ( Serial) | E15: Basic Metering | F15: Digital Power | G15: Energy Management | H15: HW | I15: Connected Product | J15: Commercialized | K15: Add from Product Portfolio RA
B16: No | C16: No | D16: DINEthernet SE EM3570,EM3570A,EM3570X,EM3570AX | E16: Basic Metering | F16: Digital Power | G16: Energy Management | H16: HW | I16: Connected Product | J16: Commercialized | K16: Add from Product Portfolio RA
B17: No | C17: No | D17: DINethernet Varis E71E3 ,E71E3A,E71E3X E71E3AX | E17: Basic Metering | F17: Digital Power | G17: Energy Management | H17: HW | I17: Connected Product | J17: Commercialized | K17: Add from Product Portfolio RA
B18: No | C18: No | D18: DVR (Brand Label) | E18: Power Quality and Power Factor Correction | F18: Digital Power | G18: Energy Management | H18: HW | I18: Connected Product | J18: End of commercialisation | K18: Add from Product Portfolio DP LoB (Laura)
B19: No | C19: No | D19: Easergy Builder | E19: Protection and Control | F19: Digital Power | G19: Energy Management | H19: SW | I19: Edge control | J19: Commercialized | K19: Add from Product Portfolio DP LoB (Laura) | L19: HTTPS | P19: Y
B20: No | C20: Yes | D20: Easergy Flair | E20: Medium Voltage Distribution and Grid Automation | F20: Digital Power | G20: Energy Management | H20: HW | I20: Connected product | J20: Commercialized | L20: Modbus Serie | S20: Y
B21: No | C21: No | D21: Easergy Flair 200 | E21: Medium Voltage Distribution and Grid Automation | F21: Digital Power | G21: Energy Management | H21: HW | I21: Connected product | J21: Commercialized | L21: Modbus Serie, Modbus TCP, DNP3, SMTP, 3,4G | S21: Y | T21: Y | Y21: Y | AA21: Y | AC21: Y
B22: No | C22: No | D22: Easergy Flite 116 | E22: Medium Voltage Distribution and Grid Automation | F22: Digital Power | G22: Energy Management | H22: HW | I22: Connected product | J22: Commercialized | L22: Modbus Serie, Modbus TCP, DNP3 | S22: Y | T22: Y | Y22: Y
B23: No | C23: No | D23: Easergy G200 | E23: Medium Voltage Distribution and Grid Automation | F23: Digital Power | G23: Energy Management | H23: HW | I23: Connected product | J23: Commercialized | L23: Modbus Serie, DNP3 | S23: Y | Y23: Y
B24: No | C24: No | D24: Easergy MiCOM C434 | E24: Protection relays | F24: Digital Power | G24: Energy Management | H24: HW | I24: Connected product | J24: End of commercialisation | L24: IEC 60870-5-104, IEC 61850, SNTP, SSH, PTP, SNMP, Modbus Serie | S24: Y | U24: Y | V24: Y | X24: SSH | AE24: Y | AF24: Y
B25: No | C25: No | D25: Easergy MiCOM Px10 | E25: Protection relays | F25: Digital Power | G25: Energy Management | H25: HW | I25: Connected product | J25: End of commercialisation | K25: Non-routable product | L25: Modbus RTU,IEC 60870-5-103, DNP | S25: Y | AE25: Y
B26: No | C26: No | D26: Easergy MiCOM Px20 | E26: Protection relays | F26: Digital Power | G26: Energy Management | H26: HW | I26: Connected product | J26: End of commercialisation | K26: Non-routable product | L26: Modbus RTU,IEC 60870-5-103, DNP | S26: Y | AE26: Y
B27: No | C27: No | D27: Easergy MiCOM Px30 | E27: Protection relays | F27: Digital Power | G27: Energy Management | H27: HW | I27: Connected product | J27: Commercialized | L27: IEC 60870-5-104, IEC 61850, SNTP, SSH, PTP, SNMP, Modbus Serie | S27: Y | X27: SSH | AE27: Y | AF27: Y
B28: No | C28: No | D28: Easergy MiCOM Px40 | E28: Protection relays | F28: Digital Power | G28: Energy Management | H28: HW | I28: Connected product | J28: Commercialized | L28: Modbus TCP, Modbus Serie,IEC 60870-5-103, DNP3, IEC 61850, SNTP | S28: Y | T28: Y | U28: Y | Y28: Y | AE28: Y | AF28: Y
B29: No | C29: No | D29: Easergy P1 | E29: Medium Voltage Distribution and Grid Automation | F29: Digital Power | G29: Energy Management | H29: HW | I29: Connected product | J29: To be Discontinued | K29: Non-routable product | L29: Modbus Serie, IEC 103 | S29: Y | AE29: IEC 103
B30: Yes | C30: No | D30: Easergy P3 | E30: Medium Voltage Distribution and Grid Automation | F30: Digital Power | G30: Energy Management | H30: HW | I30: Connected product | J30: To be Discontinued | L30: EIP, Modbus Serie, Modbus TCP, EIP, SNTP, FTP, HTTP, Telnet, DNP3, IEC60870-5-103&101, IEC61850 | N30: Y | O30: Y | P30: Y | S30: Y | T30: Y | U30: Y | X30: Y | Y30: Y | AE30: Y | AF30: Y
B31: No | C31: Yes | D31: Easergy P5 | E31: Medium Voltage Distribution and Grid Automation | F31: Digital Power | G31: Energy Management | H31: HW | I31: Connected product | J31: To be Discontinued | L31: EIP, Modbus Serie, Modbus TCP, SNTP, PTP, DNP3, IEC60870-5-103&101, IEC61850, SSH, SFTP, HTTPS | N31: Y | P31: Y | S31: Y | T31: Y | U31: Y | X31: SSH | Y31: Y | AE31: Y | AF31: Y
B32: No | C32: No | D32: Easergy P7 | E32: Medium Voltage Distribution and Grid Automation | F32: Digital Power | G32: Energy Management | H32: HW | I32: Connected product | J32: To be Discontinued | L32: Modbus Serie, Modbus TCP, SNTP, HTTPS, SFTP, SNMP, DNP3, IEC60870-5-103, IEC61850, IEC61869-9, PTP | P32: Y | S32: Y | T32: Y | U32: Y | V32: Y | Y32: Y | AB32: Y | AE32: Y | AF32: Y
B33: No | C33: No | D33: Easergy Pro | E33: Power Mgt Systems | F33: Digital Power | G33: Energy Management | H33: SW | I33: Edge control | J33: Commercialized | K33: Add from Product Portfolio DP LoB (Laura)
B34: No | C34: No | D34: Easergy PS 100 | E34: Medium Voltage Distribution and Grid Automation | F34: Digital Power | G34: Energy Management | H34: HW | I34: Connected product | J34: Commercialized | L34: Modbus Serie | S34: Y
B35: No | C35: No | D35: Easergy Studio | E35: Power Mgt Systems | F35: Digital Power | G35: Energy Management | H35: SW | I35: Connected product | J35: Commercialized | K35: Add from Product Portfolio DP LoB (Laura)
B36: Yes | C36: No | D36: Easergy T200,T200I | E36: Medium Voltage Distribution and Grid Automation | F36: Digital Power | G36: Energy Management | H36: HW | I36: Connected product | J36: Commercialized | L36: Modbus Serie , Modbus TCP, http | S36: Y | T36: Y | Y36: Y | AC36: Y
B37: No | C37: No | D37: EasyLogic AccuSine PCSU | E37: Power Quality and Power Factor Correction | F37: Digital Power | G37: Energy Management | H37: HW | I37: Connected product | J37: Commercialized | K37: Non-routable product | L37: Modbus Serie | S37: Y
B38: No | C38: No | D38: EasyLogic DM2000 | E38: Low voltage power distribution products and equipment | F38: Digital Power | G38: Energy Management | H38: HW | I38: Connected product | J38: End of commercialisation | L38: Modbus Serie, Modbus TCP? | S38: Y | T38: Y ?
B39: No | C39: No | D39: EasyLogic PM1100 | E39: Power Monitoring and Energy Monitoring Systems | F39: Digital Power | G39: Energy Management | H39: HW | I39: Connected product | J39: Commercialized | K39: Non-routable product | L39: Modbus Serie | S39: Y
B40: Yes | C40: No | D40: EasyLogic PM2000 | E40: Power Metering and Energy Monitoring Systems | F40: Digital Power | G40: Energy Management | H40: HW | I40: Connected product | J40: Commercialized | K40: Non-routable product | L40: Modbus Serie | S40: Y
...

Sheet MicroGrid
B1: =COUNTIF(Table327[Seen on BS],"Yes") -> 0 | C1: =COUNTIF(Table327[Fingerprints available],"Yes") -> 0 | D1: =COUNTA(Table327[Product range]) -> 15 | E1: =SUBTOTAL(3,D3:D17) -> 15
A2: Priority | B2: Seen on BS | C2: Fingerprints available | D2: Product range | E2: Family | F2: LOB | G2: BU | H2: Type | I2: EcoStruxure Level | J2: State | K2: Notes | L2: Protocols | M2: BacNet | N2: EIP | O2: FTP | P2: HTTP/HTTPS | Q2: KNX | R2: mDNS | S2: Modbus Series | T2: ModbusTCP | U2: SNTP | V2: SNMP | W2: SQL Server | X2: Telnet | Y2: DNP3 | Z2: Web | AA2: SMTP | AB2: SFTP | AC2: 3,4G | AD2: Wifi , IPV4,6 | AE2: IEC 60870-5-103/104/101 | AF2: IEC 61850 | AG2: Zigbee | AH2: Bluetooth | AI2: Available at GSL B'lore
B3: No | C3: No | D3: BESS ANSI | E3: Energy Storage | F3: Micro Grid | G3: Energy Management | H3: SW | I3: Edge control | J3: Commercialized | K3: Add from Product Portfolio MG LoB
B4: No | C4: No | D4: EcoStruxure Microgrid Advisor v4 (EMA) | E4: Software & Control | F4: Micro Grid | G4: Energy Management | H4: SW | I4: Analytics | J4: Commercialized | K4: Add from Product Portfolio MG LoB
B5: No | C5: No | D5: EcoStruxure Microgrid Advisor v5 (EMA) | E5: Software & Control | F5: Micro Grid | G5: Energy Management | H5: SW | I5: Analytics | J5: Commercialized | K5: Add from Product Portfolio MG LoB
B6: No | C6: No | D6: EcoStruxure Microgrid Build (EMB) | E6: Software & Control | F6: Micro Grid | G6: Energy Management | H6: SW | I6: Edge control | J6: Commercialized | K6: Add from Product Portfolio MG LoB
B7: No | C7: No | D7: EcoStruxure Microgrid Controller | E7: Software & Control | F7: Micro Grid | G7: Energy Management | H7: SW | I7: Edge control | J7: Commercialized | K7: Add from Product Portfolio MG LoB
B8: No | C8: No | D8: EcoStruxure Microgrid Maintaince (EMM) | E8: Software & Control | F8: Micro Grid | G8: Energy Management | H8: SW | I8: Edge control | J8: Commercialized | K8: Add from Product Portfolio MG LoB
B9: No | C9: No | D9: EcoStruxure Microgrid Operation (EMO-M) | E9: Software & Control | F9: Micro Grid | G9: Energy Management | H9: SW | I9: Edge control | J9: Commercialized | K9: Add from Product Portfolio MG LoB
B10: No | C10: No | D10: EMO-L | E10: Software & Control | F10: Micro Grid | G10: Energy Management | H10: SW | I10: Edge control | J10: Commercialized | K10: Add from Product Portfolio MG LoB
B11: No | C11: No | D11: FLEX ANSI | E11: System | F11: Micro Grid | G11: Energy Management | H11: SW | I11: Edge control | J11: Commercialized | K11: Add from Product Portfolio MG LoB
B12: No | C12: No | D12: FLEX IEC | E12: System | F12: Micro Grid | G12: Energy Management | H12: SW | I12: Edge control | J12: Commercialized | K12: Add from Product Portfolio MG LoB
B13: No | C13: No | D13: IEC PCU(Discontinue before 2027) | E13: Energy Storage | F13: Micro Grid | G13: Energy Management | H13: SW | I13: Edge control | J13: Commercialized | K13: Add from Product Portfolio MG LoB
B14: No | C14: No | D14: Microgrid Assessment Cloud (MGA-C) | E14: Software & Control | F14: Micro Grid | G14: Energy Management | H14: SW | I14: Edge control | J14: Commercialized | K14: Add from Product Portfolio MG LoB
... B17: No | C17: No | D17: Villaya Flex | E17: System | F17: Micro Grid | G17: Energy Management | H17: SW | I17: Edge control | J17: End of commercialisation | K17: Add from Product Portfolio MG LoB
E24: In "Product range" column different color means:
E26: Offer exists in both "IB Program - Offers List.xlsx" and "Product Portfolio.xlsx"
E28: Offer added to "IB Program - Offers List.xlsx" from "Product Portfolio.xlsx"
E30: Others are offers exist in "IB Program - Offers List.xlsx" but not exist in "Product Portfolio.xlsx"
B38: Yes | C38: No | D38: PM8000 | F38: Digital Power | G38: Energy Management | K38: duplicate
B39: Yes | C39: No | D39: Advanced Metering | F39: Digital Power | G39: Energy Management

Sheet EcoStruxure Power
B1: =COUNTIF(Table3279[Seen on BS],"Yes") -> 1 | C1: =COUNTIF(Table3279[Fingerprints available],"Yes") -> 1 | D1: =COUNTA(Table3279[Product range]) -> 32 | E1: =SUBTOTAL(3,D3:D34) -> 32
A2: Priority | B2: Seen on BS | C2: Fingerprints available | D2: Product range | E2: Family | F2: LOB | G2: BU | H2: Type | I2: EcoStruxure Level | J2: State | K2: Notes | L2: Protocols | M2: BacNet | N2: EIP | O2: FTP | P2: HTTP/HTTPS | Q2: KNX | R2: mDNS | S2: Modbus Series | T2: ModbusTCP | U2: SNTP | V2: SNMP | W2: SQL Server | X2: Telnet | Y2: DNP3 | Z2: Web | AA2: SMTP | AB2: SFTP | AC2: 3,4G | AD2: Wifi , IPV4,6 | AE2: IEC 60870-5-103/104/101 | AF2: IEC 61850 | AG2: Zigbee | AH2: Bluetooth | AI2: Available at GSL B'lore
B3: No | C3: No | D3: Aurtra | E3: Advisors & Apps | F3: EcoStruxure Power | G3: Energy Management | H3: SW | I3: Edge control | K3: Add from Product Portfolio ESXP LoB
B4: No | C4: No | D4: Classic EEH Web Team | E4: Advisors & Apps | F4: EcoStruxure Power | G4: Energy Management | H4: SW | I4: Edge control | K4: Add from Product Portfolio ESXP LoB
B5: No | C5: No | D5: Cloud Commissioning | E5: Advisors & Apps | F5: EcoStruxure Power | G5: Energy Management | H5: SW | I5: Edge control | K5: Add from Product Portfolio ESXP LoB
B6: No | C6: No | D6: Com'x(No regulatory work) | E6: Panel Server | F6: EcoStruxure Power | G6: Energy Management | H6: HW | I6: Connected Product | J6: End of commercialisation | K6: Add from Product Portfolio ESXP LoB
B7: No | C7: No | D7: Connectivity as a Service | E7: Panel Server | F7: EcoStruxure Power | G7: Energy Management | H7: SW | I7: Edge control | K7: Add from Product Portfolio ESXP LoB
B8: No | C8: No | D8: Data as a Service | E8: Advisors & Apps | F8: EcoStruxure Power | G8: Energy Management | H8: SW | I8: Edge control | K8: Add from Product Portfolio ESXP LoB
B9: No | C9: No | D9: DSA (Digital Service Admin) - Transfer from SD | E9: Advisors & Apps | F9: EcoStruxure Power | G9: Energy Management | H9: SW | I9: Edge control | K9: Add from Product Portfolio ESXP LoB
B10: No | C10: Yes | D10: EcoStruxure Asset & Power Advisor | E10: Critical Power Cooling and Racks | F10: EcoStruxure Power | G10: Energy Management | H10: SW | I10: Analytics | J10: Commercialized | K10: Should be just Asset advisor (power advisor already listed) | L10: Software
B11: No | C11: No | D11: EcoStruxure Power Commission | E11: Low voltage products and systems | F11: EcoStruxure Power | G11: Energy Management | H11: SW | I11: Edge control | J11: Commercialized | L11: Software
B12: No | C12: No | D12: EcoStruxure Power Commission Mobile | E12: Comm & Device Integration | F12: EcoStruxure Power | G12: Energy Management | H12: SW | I12: Edge control | K12: Add from Product Portfolio ESXP LoB
B13: No | C13: No | D13: EcoStruxure Transformer Expert | E13: Medium Voltage Distribution and Grid Automation | F13: EcoStruxure Power | G13: Energy Management | H13: SW | I13: Edge control | J13: Commercialized | L13: Software
B14: No | C14: No | D14: EcoStruxureEnergy Hub | E14: Power metering and energy monitoring systems | F14: EcoStruxure Power | G14: Energy Management | H14: SW | I14: Edge control | J14: Commercialized | K14: Also in the Family: Low voltage products and systems | L14: Software
B15: No | C15: No | D15: EcoStruxureFacility Expert | E15: Power Metering and Energy Monitoring Systems | F15: EcoStruxure Power | G15: Energy Management | H15: SW | I15: Edge control | J15: Commercialized | L15: Software
B16: Yes | C16: No | D16: EcoStruxurePanel Server (PAS) | E16: Power Monitoring and Energy Monitoring Systems | F16: EcoStruxure Power | G16: Energy Management | H16: HW | I16: Edge Control | J16: Commercialized | K16: Model ; 400, 500, 600(-,L,P), 700, 800(-,L,P,T,LWD) | L16: Modbus TCP, HTTPS, IPV4,6, Modbus RTU, EIP, 3,4G, | N16: Y | P16: Y | S16: Y | T16: Y | Z16: Y | AC16: Y | AD16: Y
B17: No | C17: No | D17: EcoStruxurePanel Server webpages | E17: Low voltage power distribution products and equipment | F17: EcoStruxure Power | G17: Energy Management | H17: SW | I17: Edge Control | J17: Commercialized | K17: Is this just panel server? why "webpages" | L17: Software
B18: No | C18: No | D18: EcoStruxurePower Advisor | E18: Power Metering and Energy Monitoring Systems | F18: EcoStruxure Power | G18: Energy Management | H18: SW | I18: Analytics | J18: Commercialized | L18: Software
B19: No | C19: No | D19: EEH Classic(Harish) | E19: Advisors & Apps | F19: EcoStruxure Power | G19: Energy Management | H19: SW | I19: Edge control | K19: Add from Product Portfolio ESXP LoB
B20: No | C20: No | D20: EEH Team 8 (EEH -Mobile Team) | E20: Advisors & Apps | F20: EcoStruxure Power | G20: Energy Management | H20: SW | I20: Edge control | K20: Add from Product Portfolio ESXP LoB
B21: No | C21: No | D21: EPB-SC (Ecostruxure Power and Buildings Software Companion) ( Formerly Sales Portal) | E21: Advisors & Apps | F21: EcoStruxure Power | G21: Energy Management | H21: SW | I21: Edge control | K21: Add from Product Portfolio ESXP LoB
B22: No | C22: No | D22: EPC-Web | E22: Advisors & Apps | F22: EcoStruxure Power | G22: Energy Management | H22: SW | I22: Edge control | K22: Add from Product Portfolio ESXP LoB
B23: No | C23: No | D23: ESP-209 EEH to PaS (Web and Mobile) | E23: Advisors & Apps | F23: EcoStruxure Power | G23: Energy Management | H23: SW | I23: Edge control | K23: Add from Product Portfolio ESXP LoB
B24: No | C24: No | D24: ESXP Advisor convergence | E24: Advisors & Apps | F24: EcoStruxure Power | G24: Energy Management | H24: SW | I24: Edge control | K24: Add from Product Portfolio ESXP LoB
B25: No | C25: No | D25: ESXP Energy & Chemicals (Oil & Gas) | E25: System | F25: EcoStruxure Power | G25: Energy Management | H25: SW | I25: Edge control | K25: Add from Product Portfolio ESXP LoB
B26: No | C26: No | D26: Link150 | E26: Panel Server | F26: EcoStruxure Power | G26: Energy Management | H26: HW | I26: Connected Product | J26: End of commercialisation | K26: Add from Product Portfolio ESXP LoB
B27: No | C27: No | D27: Mission Critical Solution | E27: System | F27: EcoStruxure Power | G27: Energy Management | H27: SW | I27: Edge control | K27: Add from Product Portfolio ESXP LoB
B28: No | C28: No | D28: Next Gen Advisor platform (Harish) | E28: Advisors & Apps | F28: EcoStruxure Power | G28: Energy Management | H28: SW | I28: Analytics | K28: Add from Product Portfolio ESXP LoB
B29: No | C29: No | D29: PowerTag Link | E29: Panel Server | F29: EcoStruxure Power | G29: Energy Management | H29: HW | I29: Connected Product | J29: End of commercialisation | K29: Add from Product Portfolio ESXP LoB
B30: No | C30: No | D30: SE EDGE Agent (Feb 2025) | E30: Panel Server | F30: EcoStruxure Power | G30: Energy Management | H30: SW | I30: Edge control | K30: Add from Product Portfolio ESXP LoB
B31: No | C31: No | D31: Site Server (PMSL) | E31: Power Mgt Systems | F31: EcoStruxure Power | G31: Energy Management | H31: SW | K31: Add from Product Portfolio ESXP LoB
B32: No | C32: No | D32: SLMR | E32: Panel Server | F32: EcoStruxure Power | G32: Energy Management | H32: HW | I32: Connected Product | K32: Add from Product Portfolio ESXP LoB
B33: No | C33: No | D33: SmartComm | E33: Advisors & Apps | F33: EcoStruxure Power | G33: Energy Management | H33: SW | I33: Edge control | K33: Add from Product Portfolio ESXP LoB
B34: No | C34: No | D34: SmartLink SIB | E34: Panel Server | F34: EcoStruxure Power | G34: Energy Management | H34: HW | I34: Connected Product | K34: Add from Product Portfolio ESXP LoB
E41: In "Product range" column different color means:
E43: Offer exists in both "IB Program - Offers List.xlsx" and "Product Portfolio.xlsx"
E45: Offer added to "IB Program - Offers List.xlsx" from "Product Portfolio.xlsx"
E47: Others are offers exist in "IB Program - Offers List.xlsx" but not exist in "Product Portfolio.xlsx"

Sheet Power Products
C1: =COUNTIF(Table329[Seen on BS],"Yes") -> 5 | D1: =COUNTIF(Table329[Fingerprints available],"Yes") -> 2 | E1: =COUNTA(Table329[[Product range ]]) -> 22 | AM1: Product Risk Priority - PP
A2: Extra | B2: Commonality | C2: Seen on BS | D2: Fingerprints available | E2: Product range | F2: Family | G2: LOB | H2: BU | I2: Type | J2: EcoStruxure Level | K2: State | L2: Notes | M2: Protocols | N2: Serial Only | O2: BacNet | P2: EIP | Q2: FTP | R2: HTTP/ HTTPS | S2: KNX | T2: mDNS | U2: Modbus Series | V2: Modbus TCP | W2: SNTP | X2: SNMP | Y2: SQL Server | Z2: Telnet | AA2: DNP3 | AB2: Web | AC2: SMTP | AD2: SFTP | AE2: 3,4G | AF2: WiFi, IPV4, IPv6 | AG2: IEC 60870-5-103/104/101 | AH2: IEC 61850 | AI2: Zigbee | AJ2: Column1 | AM2: High | AN2: Risk to system, entry point to the system - possible to pivot / lateral movement, has connectivity, exposable
A3: Low | C3: No | D3: No | E3: BSCM+ | F3: Low Voltage Products and Systems | G3: Power Products | H3: Energy management | I3: HW | J3: Edge control | K3: Commercialized | M3: Modbus SL | N3: Y | U3: Y | AM3: Medium
A4: Low | C4: No | D4: No | E4: ComPacT INS,INV | F4: Circuit Breakers and Switches | G4: Power Products | H4: Energy management | I4: HW | J4: Connected Product | K4: Commercialized | L4: Communication by PowerTag | M4: Zigbee (Powertag) | AI4: Y | AM4: Low | AN4: Not directly exposable, mostly serial connectivity, deep in the network architecture
A5: Low | C5: Yes | D5: No | E5: CompacT NS > 630A | F5: Circuit Breakers and Switches | G5: Power Products | H5: Energy management | I5: HW | J5: Connected Product | K5: Commercialized | L5: Modbus Serie with Enerlin'X and Micrologic or maybe natively | M5: Modbus Serie | N5: Y | U5: Y
A6: Low | C6: Yes | D6: No | E6: Compact NSX | F6: Circuit Breakers and Switches | G6: Power Products | H6: Energy management | I6: HW | J6: Connected Product | K6: Commercialized | L6: Modbus Serie & Modbus TCP with Enerlin'X, Micrologic (Use ULP to connect) or maybe natively | M6: Modbus Serie when connected to Enerlin'X IFM / BSCM+ Modbus TCP when connected to Enerlin'X IFE Zigbee with PowerTag | N6: Y | U6: Y | V6: Y | AI6: Y
A7: Low | C7: No | D7: No | E7: Enerlin'X FDM121 | F7: Power Metering and Energy Monitoring Systems | G7: Power Products | H7: Energy management | I7: HW | J7: Edge control | K7: Commercialized | M7: ULP (=S= internal) | N7: Y
A8: High | B8: Yes | C8: Yes | D8: No | E8: Enerlin'X IFE | F8: Power Metering and Energy Monitoring Systems | G8: Power Products | H8: Energy management | I8: HW | J8: Edge control | K8: Commercialized | M8: FTPS, HTTP/HTTPS, Modbus Serie, Modbus TCP, SNTP, Web, IEC61850, SNMP, SMTP, NTP, RSTP, Secure ModbusTCP, DNS | Q8: Y | R8: Y | U8: Y | V8: Y | W8: Y | X8: Y | AB8: Y | AC8: Y | AH8: Y
A9: High | B9: Yes | C9: Yes | D9: No | E9: Enerlin'X EIFE | F9: Power Metering and Energy Monitoring Systems | G9: Power Products | H9: Energy management | I9: HW | J9: Edge control | K9: Commercialized | M9: FTPS, HTTP/HTTPS, Modbus Serie, Modbus TCP, SNTP, Web, IEC61850, SNMP, SMTP, NTP, RSTP, Secure ModbusTCP | Q9: Y | R9: Y | U9: Y | V9: Y | W9: Y | X9: Y | AB9: Y | AC9: Y | AH9: Y
A10: Low | C10: No | D10: No | E10: Enerlin'X IFM | F10: Power Metering and Energy Monitoring Systems | G10: Power Products | H10: Energy management | I10: HW | J10: Edge control | K10: Commercialized | M10: Modbus SL | N10: Y | U10: Y
A11: Low | C11: No | D11: No | E11: EOCR | F11: Contactors & protection relays | G11: Power Products | H11: Energy management | I11: HW | J11: Connected Product | K11: Commercialized | L11: It is a product for China | M11: Modbus Serie | N11: Y | U11: Y
A12: Low | C12: Yes | D12: No | E12: MasterPacT MTZ | F12: Circuit Breakers and Switches | G12: Power Products | H12: Energy management | I12: HW | J12: Connected Product | K12: Commercialized | L12: *Primary connectivity is through Enerlin'X IFE/EIFE Modbus Serie by gateway or maybe natively | M12: Zigbee, IEC61850, Modbus Series, ModbusTCP, CoAP, Bluetooth low energy, NFC | U12: Y | V12: Y | AH12: Y | AI12: Y
A13: Low | C13: No | D13: No | E13: MasterPacT NT | F13: Circuit Breakers and Switches | G13: Power Products | H13: Energy management | I13: HW | J13: Connected Product | K13: End of Commercialization | L13: *Primary connectivity is through Enerlin'X IFE/EIFE Modbus Serie & Modbus TCP with Enerlin'X, Micrologic (Use ULP to connect) or maybe natively | M13: Modbus Serie when connected to Enerlin'X IFM / BSCM+ Modbus TCP when connected to Enerlin'X IFE | U13: Y | V13: Y | AC13: Y
A14: Low | C14: No | D14: No | E14: MasterPacT NW | F14: Circuit Breakers and Switches | G14: Power Products | H14: Energy management | I14: HW | J14: Connected Product | K14: End of Commercialization | L14: *Primary connectivity is through Enerlin'X IFE/EIFE Modbus Serie & Modbus TCP with Enerlin'X, Micrologic (Use ULP to connect) or maybe natively | M14: Modbus Serie when connected to Enerlin'X IFM / BSCM+ Modbus TCP when connected to Enerlin'X IFE | U14: Y | V14: Y | AC14: Y
A15: Low | C15: No | D15: Yes | E15: MasterPacT MTZ active | F15: Circuit Breaker | G15: Power Products | H15: Energy management | I15: HW | J15: Connected Product | K15: Commercialized | L15: *Primary connectivity is through Enerlin'X IFE/EIFE | M15: Modbus, Zigbee, NFC, CoAP | P15: Y | U15: Y | V15: Y
A16: Low | C16: No | D16: No | E16: PowerPact | F16: Circuit Breakers and Switches | G16: Power Products | H16: Energy management | I16: HW | J16: Connected Product | K16: Commercialized | L16: *Primary connectivity is through Enerlin'X IFE/EIFE Modbus Serie & Modbus TCP with Enerlin'X, Micrologic (Use ULP to connect) | M16: Modbus Serie, Modbus TCP and maybe more | U16: Y | V16: Y
A17: Low | C17: No | D17: Yes | E17: PrismaSeT G Active | F17: Low Voltage Products and Systems | G17: Power Products | H17: Energy management | I17: HW | J17: Connected Product | K17: End of Commercialization | L17: With gateway Lora,4G | M17: LoRa, Bluetooth, IEEE 802.15.4
A18: Low | C18: No | D18: No | E18: PrismaSeT P Active | F18: Low Voltage Products and Systems | G18: Power Products | H18: Energy management | I18: HW | J18: Connected Product | K18: End of Commercialization | L18: With gateway Lora,4G | M18: LoRa, Bluetooth, IEEE 802.15.4
A19: High | C19: No | D19: No | E19: SourcePact | F19: Source isolation switch | G19: Power Products | H19: Energy management | I19: HW | J19: Connected Product | K19: Commercialized | M19: Modbus TCP
A20: High | C20: No | D20: No | E20: Tesys Terra | F20: Contactors & protection relays | G20: Power Products | H20: Energy management | I20: HW | J20: Connected Product | K20: Commercialized | M20: Modbus SL, Modbus TCP, Ethernet IP, Profibus DP, DeviceNet | P20: Y | U20: Y | V20: Y
A21: Low | C21: No | D21: No | E21: TransferPacT | F21: Circuit Breakers and Switches | G21: Power Products | H21: Energy management | I21: HW | J21: Connected Product | K21: Commercialized | M21: Modbus SL | U21: Y
A22: High | C22: No | D22: No | E22: PAS900S/LT | J22: Edge control | K22: Commercialized | L22: It is a product for China | M22: Modbus SL, Modbus TCP, Zigbee, Wifi, HTTPS, 4G, SNTP, DHCP | U22: Y | V22: Y | W22: Y | AB22: Y | AE22: Y | AF22: Y
A23: High | C23: No | D23: No | E23: PAS700 (Pocket HUB) | J23: Edge control | K23: Commercialized | L23: It is a product for China | M23: Modbus SL, Modbus TCP,, Wifi, HTTPS, SNTP | U23: Y | V23: Y | W23: Y | AB23: Y | AF23: Y
C24: No | D24: No | E24: Acti9 Active | F24: Low Voltage Products and systems | G24: Power Products | H24: Energy Management | I24: HW | J24: ? | K24: Commercialized | L24: Distribution | M24: In built connectivity (use with PAS)

Sheet Secure Power
A1: =COUNTIF(Table54810[Seen on BS],"Yes") -> 3 | B1: =COUNTIF(Table54810[Fingerprints available],"Yes") -> 7 | E1: =COUNTA(Table54810[Product range]) -> 24
A2: Seen on BS | B2: Fingerprints available | C2: NMC | D2: SP LOB | E2: Product range | F2: Family | G2: LOB | H2: BU | I2: Type | J2: EcoStruxuretruxure Level | K2: State | L2: Notes | M2: Protocols | N2: BacNet | O2: EIP | P2: FTP | Q2: HTTP/HTTPS | R2: KNX | S2: mDNS | T2: Modbus Series | U2: ModbusTCP | V2: SNTP | W2: SNMP | X2: SQL Server | Y2: Telnet | Z2: DNP3 | AA2: Web | AB2: SMTP | AC2: SFTP | AD2: 3,4G | AE2: Wifi , IPV4,6 | AF2: IEC 60870-5-103/104/101 | AG2: IEC 61850 | AH2: Zigbee | AI2: Other | AK2: bmm proposal
A3: No | B3: No | C3: Easy NMC | D3: T&E | E3: Easy Basic Rack PDU | F3: IT Power Distribution | G3: Critical Power, Cooling and Racks | H3: Secure Power | I3: HW | J3: No information | K3: Commercialized | M3: No information | AK3: Easy NMC
A4: No | B4: Yes | C4: Easy NMC | D4: Cooling | E4: Easy Cooling Row CW | F4: Cooling Solutions | G4: Secure Power | H4: Energy Management | I4: HW | J4: Connected product | K4: Commercialized | M4: Modbus RTU, Modbus TCP | T4: Y | U4: Y | AK4: Easy NMC
A5: No | B5: No | C5: Easy NMC | D5: T&E | E5: Easy Micro Data Center Serie (C, R, S) | F5: IT Racks and Accessories | G5: Secure Power | H5: Energy Management | I5: HW | J5: Connected product | K5: Commercialized | L5: Phone and application available | M5: No information | AA5: Y | AK5: Easy NMC
A6: Yes | B6: No | C6: NMC | D6: T&E | E6: EcoStruxure Micro Data Centers
A7: No | B7: Yes | C7: Easy NMC | D7: T&E | E7: Easy UPS 1 Ph On-Line | F7: Uninterruptible Power Supply (UPS) | G7: Secure Power | H7: Energy Management | I7: HW | J7: Connected product | K7: Commercialized | M7: Modbus & SNMP | T7: Y | U7: Y? | W7: Y | AK7: Easy NMC
A8: No | B8: Yes | C8: Easy 3P NMC | D8: DCS | E8: Easy UPS (3S, 3M, 3L) | F8: Uninterruptible Power Supply (UPS) | G8: Secure Power | H8: Energy Management | I8: HW | J8: Connected product | K8: Commercialized | M8: RS485, dry contacts, Ethernet (SNMP, Modbus, TCP/IP, BACnet) & Web | N8: Y | T8: Y | U8: ? | W8: Y | AK8: Easy NMC
A9: No | B9: No | C9: Easy NMC | D9: T&E | E9: Easy UPS | F9: Uninterruptible Power Supply (UPS) | G9: Secure Power | H9: Energy Management | I9: HW | J9: Connected product | K9: Commercialized | M9: Web, SSH, HTTPS, Modbus (Not sure) | T9: Y? | U9: Y? | W9: Y | AA9: Y | AK9: Easy NMC
A10: No | B10: No | C10: Cloud | D10: Software | E10: EcoStruxuretruxure IT Advisor | F10: Data Center Software | G10: Secure Power | H10: Energy Management | I10: SW | J10: Analytics | K10: Commercialized | M10: Software | AK10: Easy NMC
A11: No | B11: No | C11: Cloud | D11: Software | E11: EcoStruxuretruxure IT Expert | F11: Data Center Software | G11: Secure Power | H11: Energy Management | I11: SW | J11: Edge control | K11: Commercialized | M11: Software
A12: No | B12: No | C12: Gateway | D12: Software | E12: EcoStruxuretruxure IT Gateway NUC | F12: Data Center Software | G12: Secure Power | H12: Energy Management | I12: HW | J12: Connected product | K12: End of commercialization | M12: SNMP, Modbus RTU, Modbus TCP, HTTP/HTTPS,FTP | P12: Y | Q12: Y | T12: Y | U12: Y | W12: Y | AK12: Easy 3P NMC
A13: No | B13: No | C13: Cloud | D13: Software | E13: EcoStruxuretruxure IT SmartConnect | F13: Data Center Software | G13: Secure Power | H13: Energy Management | I13: SW | J13: Edge control | K13: Commercialized | M13: Software | AK13: Easy 3P NMC
A14: No | B14: No | C14: NMC3 | D14: DCS | E14: Galaxy PW Gen 2 | F14: Uninterruptible Power Supply (UPS) | G14: Secure Power | H14: Energy Management | I14: HW | J14: Connected product | K14: Commercialized | M14: Modbus Series , Web,SNMP | T14: Y | W14: Y | AA14: Y | AK14: Easy 3P NMC
A15: No | B15: No | C15: NMC3 | D15: DCS | E15: Galaxy VM | F15: Uninterruptible Power Supply (UPS) | G15: Secure Power | H15: Energy Management | I15: HW | J15: Connected product | K15: Commercialized | M15: Modbus (SCADA) , Modbus TCP/IP , Modbus RTU | T15: Y | U15: Y | AK15: Easy 3P NMC
A16: No | B16: No | C16: NMC3 | D16: DCS | E16: Galaxy VX | F16: Uninterruptible Power Supply (UPS) | G16: Secure Power | H16: Energy Management | I16: HW | J16: Connected product | K16: Commercialized | M16: Modbus TCP/IP & Modbus Series, Web,SNMP | P16: Mail | T16: Y | U16: Y | W16: Y | AK16: Easy NMC
A17: No | B17: Yes | C17: NMC4 | D17: DCS | E17: Agilis (Galaxy VL, VS, VXL) | F17: Uninterruptible Power Supply (UPS) | G17: Secure Power | H17: Energy Management | I17: HW | J17: Connected product | K17: Commercialized | M17: Modbus (SCADA) , Modbus TCP/IP , Modbus RTU | T17: Y | U17: Y | AK17: Easy NMC
A18: No | B18: No | C18: NMC3 | D18: Software | E18: NetBotz 250 (A) | F18: Security and Environmental Monitoring | G18: Secure Power | H18: Energy Management | I18: HW | J18: Connected product | K18: Commercialized | M18: HTTPS, SNMP, TCP/IP, SSH? | Q18: Y | U18: Y | W18: Y | AA18: Y? | AI18: SSH? | AK18: Easy NMC
A19: No | B19: No | C19: Software | D19: Software | E19: NetBotz 750 | AK19: Easy NMC
A20: Yes | B20: No | C20: NMC | D20: T&E | E20: NetShelter Rack PDUs | F20: IT Power Distribution | G20: Secure Power | H20: Energy Management | I20: HW | J20: Connected product | K20: Commercialized | M20: Modbus ? | T20: Y? | U20: Y? | AK20: Cloud
A21: No | B21: No | C21: Software | D21: Software | E21: PowerChute Network Shutdown | F21: Data Center Software | G21: Secure Power | H21: Energy Management | I21: SW | J21: Edge control | K21: Commercialized | M21: Software | AK21: ?
A22: No | B22: Yes | C22: NMC | D22: T&E | E22: Smart-UPS | F22: Uninterruptible Power Supply (UPS) | G22: Secure Power | H22: Energy Management | I22: HW | J22: Connected product | K22: Commercialized | M22: SNMP & Web, FTP& Modbus Serie with optional card | P22: Y | T22: Y | AA22: Y | AK22: NMC4
A23: No | B23: Yes | C23: NMC | D23: T&E | E23: Symmetra (1P) | F23: Uninterruptible Power Supply (UPS) | G23: Critical Power, Cooling and Racks | H23: Secure Power | I23: HW | J23: No information | K23: Commercialized | M23: No information | AK23: NMC4
A24: Yes | B24: No | C24: NMC | D24: DCS | E24: Symmetra PX (3P)
A25: No | B25: No | C25: NMC | D25: Cooling | E25: Unfilair | F25: Cooling Solutions | G25: Secure Power | H25: Energy Management | I25: HW | J25: Connected product | K25: Commercialized | M25: SNMP, Modbus TCP/IP, Modbus RTU, BacNet | N25: Y | T25: Y | U25: Y | W25: Y | AK25: drop
A26: No | B26: Yes | C26: Software | D26: Software | E26: Data Center Expert
AK27: USB

Sheet Secure Power (OLD)
A1: =COUNTIF(Table548[Seen on BS],"Yes") -> 4 | B1: =COUNTIF(Table548[Fingerprints available],"Yes") -> 14 | E1: =COUNTA(Table548[Product range]) -> 93
A2: Seen on BS | B2: Fingerprints available | C2: NMC | D2: Column1 | E2: Product range | F2: Family | G2: LOB | H2: BU | I2: Type | J2: EcoStruxuretruxure Level | K2: State | L2: Notes | M2: Protocols | N2: BacNet | O2: EIP | P2: FTP | Q2: HTTP/HTTPS | R2: KNX | S2: mDNS | T2: Modbus Series | U2: ModbusTCP | V2: SNTP | W2: SNMP | X2: SQL Server | Y2: Telnet | Z2: DNP3 | AA2: Web | AB2: SMTP | AC2: SFTP | AD2: 3,4G | AE2: Wifi , IPV4,6 | AF2: IEC 60870-5-103/104/101 | AG2: IEC 61850 | AH2: Zigbee | AI2: Other | AK2: bmm proposal
A3: No | B3: No | C3: Cooling: ACRC chilled water AFC | E3: Active flow controller | F3: IT Racks and Accessories | G3: Secure Power | H3: Energy Management | I3: HW | J3: Connected product | K3: Commercialized | M3: Modbus Series | T3: Y | AK3: Cooling: ACRC chilled water AFC
A4: No | B4: No | C4: home - drop | E4: Back UPS SX3 | F4: Uninterruptible Power Supply (UPS) | G4: Critical Power, Cooling and Racks | H4: Secure Power | I4: HW | J4: No information | K4: End of commercialization | L4: Seems no internet protocol | M4: No information | AK4: home - drop
A5: No | B5: Yes | C5: home - drop | E5: Back-UPS | F5: Uninterruptible Power Supply (UPS) | G5: Critical Power, Cooling and Racks | H5: Secure Power | I5: HW | J5: No information | K5: Commercialized | M5: No information | AK5: home - drop
A6: No | B6: No | C6: home - drop | E6: Back-UPS Connect | F6: Uninterruptible Power Supply (UPS) | G6: Secure Power | H6: Energy Management | I6: HW | J6: Connected product | K6: Commercialized | L6: Wifi via router ? | M6: No information | AE6: Y | AK6: home - drop
A7: No | B7: Yes | C7: home - drop | E7: Back-UPS Pro | F7: Uninterruptible Power Supply (UPS) | G7: Secure Power | H7: Energy Management | I7: HW | J7: Connected product | K7: Commercialized | L7: Ethernet | M7: No information | AK7: home - drop
A8: No | B8: No | C8: ??? | E8: Console LCD Netshelter | F8: IT Racks and Accessories | G8: Critical Power, Cooling and Racks | H8: Secure Power | I8: HW | J8: No information | K8: Commercialized | M8: No information | AK8: ???
A9: No | B9: Yes | C9: ??? | E9: Cooling Distribution and Piping Accessories | F9: Cooling Solutions | G9: Critical Power, Cooling and Racks | H9: Secure Power | I9: HW | J9: No information | K9: Commercialized | M9: No information | AK9: ???
A10: No | B10: No | C10: Easy NMC | E10: Easy Basic Rack PDU | F10: IT Power Distribution | G10: Critical Power, Cooling and Racks | H10: Secure Power | I10: HW | J10: No information | K10: Commercialized | M10: No information | AK10: Easy NMC
A11: No | B11: Yes | C11: Easy NMC | E11: Easy Cooling Row CW | F11: Cooling Solutions | G11: Secure Power | H11: Energy Management | I11: HW | J11: Connected product | K11: Commercialized | M11: Modbus RTU, Modbus TCP | T11: Y | U11: Y | AK11: Easy NMC
